Workbook
Name Category_List: #REF!
Name Diet_List: #REF!
Name Habitat_List: #REF!
Name IUCN_List: #REF!
Name Species_List: #REF!
Name Zoo_category: Zoo_Data!$H$2:$H$11
Name Zoo_diet: Zoo_Data!$D$2:$D$11
Name Zoo_habitat: Zoo_Data!$E$2:$E$11
Name Zoo_iucn: Zoo_Data!$F$2:$F$11
Name Zoo_length: Zoo_Data!$C$2:$C$11
Name Zoo_pop: Zoo_Data!$G$2:$G$11
Name Zoo_species: Zoo_Data!$A$2:$A$11
Name Zoo_weight: Zoo_Data!$B$2:$B$11

Sheet Zoo_Data
A1: species | B1: avg_weight_kg | C1: avg_length_cm | D1: diet | E1: habitat | F1: iucn_status | G1: population_estimate | H1: category
A2: rock_hyrax | B2: 4.50 | C2: 55.00 | D2: Herbivore | E2: rocky | F2: Least Concern | G2: 50000 | H2: Hyrax
A3: bush_hyrax | B3: 3.8 | C3: 45 | D3: Herbivore | E3: savanna | F3: Near Threatened | G3: 12000 | H3: Hyrax
A4: tree_hyrax | B4: 2.9 | C4: 42 | D4: Herbivore | E4: forest | F4: Vulnerable | G4: 5000 | H4: Hyrax
A5: meerkat | B5: 1 | C5: 25 | D5: Omnivore | E5: savanna | F5: Least Concern | G5: 25000 | H5: Meerkat
A6: african_elephant | B6: 5400 | C6: 700 | D6: Herbivore | E6: savanna | F6: Endangered | G6: 415000 | H6: Elephant
A7: rock_rabbit | B7: 2.3 | C7: 40 | D7: Herbivore | E7: rocky | F7: Least Concern | G7: 8000 | H7: Rock Rabbit
A8: yellow_mongoose | B8: 0.8 | C8: 28 | D8: Omnivore | E8: grassland | F8: Least Concern | G8: 400000 | H8: Mongoose
A9: elephant_shrew | B9: 0.5 | C9: 20 | D9: Omnivore | E9: forest | F9: Near Threatened | G9: 30000 | H9: Elephant Shrew
A10: cape_hyrax | B10: 3.9 | C10: 47 | D10: Herbivore | E10: rocky | F10: Least Concern | G10: 60000 | H10: Hyrax
A11: desert_meerkat | B11: 0.9 | C11: 23 | D11: Omnivore | E11: desert | F11: Vulnerable | G11: 15000 | H11: Meerkat

Sheet helpers
A1: Risk_Level (from Zoo_Data)
A2: =IF(Zoo_Data!F2="Endangered","High",) -> 0

Sheet Zoo_Dashboard
A1: Dashboard
A3: Total Species | B3: =COUNTA(Zoo_Data!$A$2:$A$11) -> 10
A4: Avg Weight (kg) | B4: =ROUND(AVERAGE(Zoo_Data!$B$2:$B$11),2) -> 601.79
A5: Avg Population | B5: =ROUND(AVERAGE(Zoo_Data!$G$2:$G$11),0) -> 107778
A6: Endangered Count | B6: =COUNTIF(Zoo_Data!$F$2:$F$11,"Endangered") -> 1
A9: Category | B9: Avg Weight
A10: Elephant | B10: =AVERAGEIF(Zoo_Data!$H$2:$H$11,"Elephant",Zoo_Data!$B$2:$B$11) -> 5400
A11: Elephant Shrew | B11: =AVERAGEIF(Zoo_Data!$H$2:$H$11,"Elephant Shrew",Zoo_Data!$B$2:$B$11) -> 0.5
A12: Hyrax | B12: =AVERAGEIF(Zoo_Data!$H$2:$H$11,"Hyrax",Zoo_Data!$B$2:$B$11) -> 3.5333333
A13: Meerkat | B13: =AVERAGEIF(Zoo_Data!$H$2:$H$11,"Meerkat",Zoo_Data!$B$2:$B$11) -> 0.95
A14: Mongoose | B14: =AVERAGEIF(Zoo_Data!$H$2:$H$11,"Mongoose",Zoo_Data!$B$2:$B$11) -> 0.8
A15: Rock Rabbit | B15: =AVERAGEIF(Zoo_Data!$H$2:$H$11,"Rock Rabbit",Zoo_Data!$B$2:$B$11) -> 2.3
A30: IUCN | B30: Count
A31: Least Concern | B31: =COUNTIF(Zoo_Data!$F$2:$F$11,"Least Concern") -> 5
A32: Near Threatened | B32: =COUNTIF(Zoo_Data!$F$2:$F$11,"Near Threatened") -> 2
A33: Vulnerable | B33: =COUNTIF(Zoo_Data!$F$2:$F$11,"Vulnerable") -> 2
A34: Endangered | B34: =COUNTIF(Zoo_Data!$F$2:$F$11,"Endangered") -> 1
A35: Critically Endangered | B35: =COUNTIF(Zoo_Data!$F$2:$F$11,"Critically Endangered") -> 0

Sheet guide
A1: 🧩 1️⃣ Why We “Stringify” (use quotes like "Near Threatened")
A3: In Excel formulas such as COUNTIF, "text" criteria must be enclosed in quotes because:
A5: quotes tell Excel that it’s a literal value, not a reference or formula.
A7: otherwise Excel would look for a named range or variable called Near Threatened, which doesn’t exist.
A9: so:
A11: =COUNTIF(Zoo_Data!F2:F11,"Near Threatened") -> 2
A13: means:
A15: count cells in F2:F11 whose text exactly equals “Near Threatened”.
A17: if instead you had a cell (say A2) containing that text, you could use a reference without quotes:
A19: =COUNTIF(Zoo_Data!F2:F11, A2) -> 0
A21: 🧠 rule of thumb:
A23: "quoted" = literal text you typed
A25: A2 = value inside a cell
A29: 📊 2️⃣ How Dashboards Are Built (step-by-step)
A31: Dashboards are just a polished, interactive summary sheet that combines:
A32: 1️⃣ Data sheet(s) → your Zoo_Data table
A33: 2️⃣ Helper summaries → COUNTIF, AVERAGEIF, etc.
A34: 3️⃣ Visualisation elements → charts, slicers, KPI cards
A36: 🧱 Step-by-step layout:
A38: 🔹 Step 1 — Prep the data
A40: You already did this: a clean table with headers, formatted as a table (Ctrl+T).
A42: 🔹 Step 2 — Create your “Summary” area
A44: In a new sheet, make small tables like:
A46: Metric | B46: Formula | C46: Result
A47: Endangered count | B47: =COUNTIF(Zoo_Data[iucn_status],"Endangered") | C47: 1
A48: Average weight of Safe species | B48: =AVERAGEIF(Zoo_Data[risk_level],"Safe",Zoo_Data[avg_weight_kg]) | C48: ...
A50: 🔹 Step 3 — Add visuals
A52: Select your summary range and insert Column or Doughnut charts.
A54: Add Conditional Formatting icons (traffic lights or bars).
A56: Add Cards (merged cells with large numbers) for quick KPIs.
A58: 🔹 Step 4 — Add interactivity (optional)
A60: Use:
A62: Slicers (Insert → Slicer → choose iucn_status or diet)
A64: Pivot Charts for filtered visual summaries
A66: 🔹 Step 5 — Style it
A68: use consistent colours (e.g. red = high risk, green = safe)
A70: hide gridlines
A72: bold the main KPIs
... A85: coloured KPI cards
B90: 🧩 Excel Formula Knowledge Master Sheet
...
